<?xml version="1.0" ?>
<mujoco model="allegro_hand_with_sensors">
  <compiler angle="radian"/>

  <default>
    <geom friction="1.0 0.1 0.1" margin="0.001"/>
    <joint armature="0.01" damping="0.1"/>
  </default>

  <asset>
    <material name="hand_material" rgb="0.9 0.6 0.4" reflectance="0.2"/>
    <material name="red_sensor" rgb="0.8 0.1 0.1" reflectance="0.2"/>
    <material name="blue_sensor" rgb="0.1 0.1 0.8" reflectance="0.2"/>
  </asset>

  <worldbody>
    <!-- Left Allegro Hand -->
    <body name="allegro_left_hand_base">
      <inertial mass="1.0" diaginv="1 1 1"/>
      <geom name="left_palm" type="box" size="0.05 0.04 0.03" material="hand_material"/>

      <!-- Left Thumb chain (4 joints) -->
      <body name="allegro_left_thumb_link_0" pos="0 0 0.05">
        <inertial mass="0.1" diaginv="10 10 10"/>
        <geom type="cylinder" size="0.01 0.03" material="hand_material"/>
        <joint name="left_hand_joint_0" type="hinge" axis="1 0 0" range="-1.57 1.57"/>

        <body name="allegro_left_thumb_link_1" pos="0 0 0.04">
          <inertial mass="0.08" diaginv="12.5 12.5 12.5"/>
          <geom type="cylinder" size="0.009 0.03" material="hand_material"/>
          <joint name="left_hand_joint_1" type="hinge" axis="1 0 0" range="-1.57 1.57"/>

          <body name="allegro_left_thumb_link_2" pos="0 0 0.035">
            <inertial mass="0.06" diaginv="16.67 16.67 16.67"/>
            <geom type="cylinder" size="0.008 0.025" material="hand_material"/>
            <joint name="left_hand_joint_2" type="hinge" axis="1 0 0" range="-1.57 1.57"/>

            <body name="allegro_left_thumb_link_3" pos="0 0 0.03">
              <inertial mass="0.05" diaginv="20 20 20"/>
              <geom type="cylinder" size="0.007 0.02" material="hand_material"/>
              <joint name="left_hand_joint_3" type="hinge" axis="1 0 0" range="-1.57 1.57"/>
              <site name="left_thumb_touch" type="sphere" size="0.005" pos="0 0 0.02" material="red_sensor"/>
              <site name="left_thumb_touch_1" type="sphere" size="0.005" pos="0 0.01 0.02" material="red_sensor"/>
            </body>
          </body>
        </body>
      </body>

      <!-- Left Index finger chain (4 joints) -->
      <body name="allegro_left_index_link_0" pos="0.02 0 0.05">
        <inertial mass="0.1" diaginv="10 10 10"/>
        <geom type="cylinder" size="0.01 0.03" material="hand_material"/>
        <joint name="left_hand_joint_4" type="hinge" axis="1 0 0" range="-1.57 1.57"/>

        <body name="allegro_left_index_link_1" pos="0 0 0.04">
          <inertial mass="0.08" diaginv="12.5 12.5 12.5"/>
          <geom type="cylinder" size="0.009 0.03" material="hand_material"/>
          <joint name="left_hand_joint_5" type="hinge" axis="1 0 0" range="-1.57 1.57"/>

          <body name="allegro_left_index_link_2" pos="0 0 0.035">
            <inertial mass="0.06" diaginv="16.67 16.67 16.67"/>
            <geom type="cylinder" size="0.008 0.025" material="hand_material"/>
            <joint name="left_hand_joint_6" type="hinge" axis="1 0 0" range="-1.57 1.57"/>

            <body name="allegro_left_index_link_3" pos="0 0 0.03">
              <inertial mass="0.05" diaginv="20 20 20"/>
              <geom type="cylinder" size="0.007 0.02" material="hand_material"/>
              <joint name="left_hand_joint_7" type="hinge" axis="1 0 0" range="-1.57 1.57"/>
              <site name="left_index_touch" type="sphere" size="0.005" pos="0 0 0.02" material="red_sensor"/>
              <site name="left_index_touch_1" type="sphere" size="0.005" pos="0 0.01 0.02" material="red_sensor"/>
            </body>
          </body>
        </body>
      </body>

      <!-- Left Middle finger chain (4 joints) -->
      <body name="allegro_left_middle_link_0" pos="0.04 0 0.05">
        <inertial mass="0.1" diaginv="10 10 10"/>
        <geom type="cylinder" size="0.01 0.03" material="hand_material"/>
        <joint name="left_hand_joint_8" type="hinge" axis="1 0 0" range="-1.57 1.57"/>

        <body name="allegro_left_middle_link_1" pos="0 0 0.04">
          <inertial mass="0.08" diaginv="12.5 12.5 12.5"/>
          <geom type="cylinder" size="0.009 0.03" material="hand_material"/>
          <joint name="left_hand_joint_9" type="hinge" axis="1 0 0" range="-1.57 1.57"/>

          <body name="allegro_left_middle_link_2" pos="0 0 0.035">
            <inertial mass="0.06" diaginv="16.67 16.67 16.67"/>
            <geom type="cylinder" size="0.008 0.025" material="hand_material"/>
            <joint name="left_hand_joint_10" type="hinge" axis="1 0 0" range="-1.57 1.57"/>

            <body name="allegro_left_middle_link_3" pos="0 0 0.03">
              <inertial mass="0.05" diaginv="20 20 20"/>
              <geom type="cylinder" size="0.007 0.02" material="hand_material"/>
              <joint name="left_hand_joint_11" type="hinge" axis="1 0 0" range="-1.57 1.57"/>
              <site name="left_middle_touch" type="sphere" size="0.005" pos="0 0 0.02" material="red_sensor"/>
              <site name="left_middle_touch_1" type="sphere" size="0.005" pos="0 0.01 0.02" material="red_sensor"/>
            </body>
          </body>
        </body>
      </body>

      <!-- Left Ring finger chain (4 joints) -->
      <body name="allegro_left_ring_link_0" pos="0.06 0 0.05">
        <inertial mass="0.1" diaginv="10 10 10"/>
        <geom type="cylinder" size="0.01 0.03" material="hand_material"/>
        <joint name="left_hand_joint_12" type="hinge" axis="1 0 0" range="-1.57 1.57"/>

        <body name="allegro_left_ring_link_1" pos="0 0 0.04">
          <inertial mass="0.08" diaginv="12.5 12.5 12.5"/>
          <geom type="cylinder" size="0.009 0.03" material="hand_material"/>
          <joint name="left_hand_joint_13" type="hinge" axis="1 0 0" range="-1.57 1.57"/>

          <body name="allegro_left_ring_link_2" pos="0 0 0.035">
            <inertial mass="0.06" diaginv="16.67 16.67 16.67"/>
            <geom type="cylinder" size="0.008 0.025" material="hand_material"/>
            <joint name="left_hand_joint_14" type="hinge" axis="1 0 0" range="-1.57 1.57"/>

            <body name="allegro_left_ring_link_3" pos="0 0 0.03">
              <inertial mass="0.05" diaginv="20 20 20"/>
              <geom type="cylinder" size="0.007 0.02" material="hand_material"/>
              <joint name="left_hand_joint_15" type="hinge" axis="1 0 0" range="-1.57 1.57"/>
              <site name="left_ring_touch" type="sphere" size="0.005" pos="0 0 0.02" material="red_sensor"/>
              <site name="left_ring_touch_1" type="sphere" size="0.005" pos="0 0.01 0.02" material="red_sensor"/>
            </body>
          </body>
        </body>
      </body>
    </body>

    <!-- Right Allegro Hand (mirror) -->
    <body name="allegro_right_hand_base">
      <inertial mass="1.0" diaginv="1 1 1"/>
      <geom name="right_palm" type="box" size="0.05 0.04 0.03" material="hand_material"/>

      <!-- Right Thumb chain (4 joints) -->
      <body name="allegro_right_thumb_link_0" pos="0 0 0.05">
        <inertial mass="0.1" diaginv="10 10 10"/>
        <geom type="cylinder" size="0.01 0.03" material="hand_material"/>
        <joint name="right_hand_joint_0" type="hinge" axis="1 0 0" range="-1.57 1.57"/>

        <body name="allegro_right_thumb_link_1" pos="0 0 0.04">
          <inertial mass="0.08" diaginv="12.5 12.5 12.5"/>
          <geom type="cylinder" size="0.009 0.03" material="hand_material"/>
          <joint name="right_hand_joint_1" type="hinge" axis="1 0 0" range="-1.57 1.57"/>

          <body name="allegro_right_thumb_link_2" pos="0 0 0.035">
            <inertial mass="0.06" diaginv="16.67 16.67 16.67"/>
            <geom type="cylinder" size="0.008 0.025" material="hand_material"/>
            <joint name="right_hand_joint_2" type="hinge" axis="1 0 0" range="-1.57 1.57"/>

            <body name="allegro_right_thumb_link_3" pos="0 0 0.03">
              <inertial mass="0.05" diaginv="20 20 20"/>
              <geom type="cylinder" size="0.007 0.02" material="hand_material"/>
              <joint name="right_hand_joint_3" type="hinge" axis="1 0 0" range="-1.57 1.57"/>
              <site name="right_thumb_touch" type="sphere" size="0.005" pos="0 0 0.02" material="blue_sensor"/>
              <site name="right_thumb_touch_1" type="sphere" size="0.005" pos="0 0.01 0.02" material="blue_sensor"/>
            </body>
          </body>
        </body>
      </body>

      <!-- Right Index finger chain (4 joints) -->
      <body name="allegro_right_index_link_0" pos="-0.02 0 0.05">
        <inertial mass="0.1" diaginv="10 10 10"/>
        <geom type="cylinder" size="0.01 0.03" material="hand_material"/>
        <joint name="right_hand_joint_4" type="hinge" axis="1 0 0" range="-1.57 1.57"/>

        <body name="allegro_right_index_link_1" pos="0 0 0.04">
          <inertial mass="0.08" diaginv="12.5 12.5 12.5"/>
          <geom type="cylinder" size="0.009 0.03" material="hand_material"/>
          <joint name="right_hand_joint_5" type="hinge" axis="1 0 0" range="-1.57 1.57"/>

          <body name="allegro_right_index_link_2" pos="0 0 0.035">
            <inertial mass="0.06" diaginv="16.67 16.67 16.67"/>
            <geom type="cylinder" size="0.008 0.025" material="hand_material"/>
            <joint name="right_hand_joint_6" type="hinge" axis="1 0 0" range="-1.57 1.57"/>

            <body name="allegro_right_index_link_3" pos="0 0 0.03">
              <inertial mass="0.05" diaginv="20 20 20"/>
              <geom type="cylinder" size="0.007 0.02" material="hand_material"/>
              <joint name="right_hand_joint_7" type="hinge" axis="1 0 0" range="-1.57 1.57"/>
              <site name="right_index_touch" type="sphere" size="0.005" pos="0 0 0.02" material="blue_sensor"/>
              <site name="right_index_touch_1" type="sphere" size="0.005" pos="0 0.01 0.02" material="blue_sensor"/>
            </body>
          </body>
        </body>
      </body>

      <!-- Right Middle finger chain (4 joints) -->
      <body name="allegro_right_middle_link_0" pos="-0.04 0 0.05">
        <inertial mass="0.1" diaginv="10 10 10"/>
        <geom type="cylinder" size="0.01 0.03" material="hand_material"/>
        <joint name="right_hand_joint_8" type="hinge" axis="1 0 0" range="-1.57 1.57"/>

        <body name="allegro_right_middle_link_1" pos="0 0 0.04">
          <inertial mass="0.08" diaginv="12.5 12.5 12.5"/>
          <geom type="cylinder" size="0.009 0.03" material="hand_material"/>
          <joint name="right_hand_joint_9" type="hinge" axis="1 0 0" range="-1.57 1.57"/>

          <body name="allegro_right_middle_link_2" pos="0 0 0.035">
            <inertial mass="0.06" diaginv="16.67 16.67 16.67"/>
            <geom type="cylinder" size="0.008 0.025" material="hand_material"/>
            <joint name="right_hand_joint_10" type="hinge" axis="1 0 0" range="-1.57 1.57"/>

            <body name="allegro_right_middle_link_3" pos="0 0 0.03">
              <inertial mass="0.05" diaginv="20 20 20"/>
              <geom type="cylinder" size="0.007 0.02" material="hand_material"/>
              <joint name="right_hand_joint_11" type="hinge" axis="1 0 0" range="-1.57 1.57"/>
              <site name="right_middle_touch" type="sphere" size="0.005" pos="0 0 0.02" material="blue_sensor"/>
              <site name="right_middle_touch_1" type="sphere" size="0.005" pos="0 0.01 0.02" material="blue_sensor"/>
            </body>
          </body>
        </body>
      </body>

      <!-- Right Ring finger chain (4 joints) -->
      <body name="allegro_right_ring_link_0" pos="-0.06 0 0.05">
        <inertial mass="0.1" diaginv="10 10 10"/>
        <geom type="cylinder" size="0.01 0.03" material="hand_material"/>
        <joint name="right_hand_joint_12" type="hinge" axis="1 0 0" range="-1.57 1.57"/>

        <body name="allegro_right_ring_link_1" pos="0 0 0.04">
          <inertial mass="0.08" diaginv="12.5 12.5 12.5"/>
          <geom type="cylinder" size="0.009 0.03" material="hand_material"/>
          <joint name="right_hand_joint_13" type="hinge" axis="1 0 0" range="-1.57 1.57"/>

          <body name="allegro_right_ring_link_2" pos="0 0 0.035">
            <inertial mass="0.06" diaginv="16.67 16.67 16.67"/>
            <geom type="cylinder" size="0.008 0.025" material="hand_material"/>
            <joint name="right_hand_joint_14" type="hinge" axis="1 0 0" range="-1.57 1.57"/>

            <body name="allegro_right_ring_link_3" pos="0 0 0.03">
              <inertial mass="0.05" diaginv="20 20 20"/>
              <geom type="cylinder" size="0.007 0.02" material="hand_material"/>
              <joint name="right_hand_joint_15" type="hinge" axis="1 0 0" range="-1.57 1.57"/>
              <site name="right_ring_touch" type="sphere" size="0.005" pos="0 0 0.02" material="blue_sensor"/>
              <site name="right_ring_touch_1" type="sphere" size="0.005" pos="0 0.01 0.02" material="blue_sensor"/>
            </body>
          </body>
        </body>
      </body>
    </body>
  </worldbody>
</mujoco>
