<?xml version="1.0" ?>
<mujoco model="nuclear_glovebox_teleoperation">
  <compiler angle="radian" inertiafromgeom="true"/>

  <option timestep="0.002" gravity="0 0 -9.81"/>

  <default>
    <geom friction="1.0 0.1 0.1" margin="0.001"/>
    <joint armature="0.01" damping="0.1"/>
  </default>

  <asset>
    <texture name="grid" type="2d" builtin="checker" rgb1="0.1 0.1 0.1" rgb2="0.9 0.9 0.9" width="300" height="300"/>
    <material name="grid" texture="grid" texrepeat="8 8" reflectance="0.7"/>
    <material name="glovebox_material" reflectance="0.3"/>
    <material name="hand_material" reflectance="0.2"/>
    <material name="red" reflectance="0.2"/>
    <material name="blue" reflectance="0.2"/>
  </asset>

  <worldbody>
    <!-- Ground plane -->
    <geom name="ground" type="plane" size="1 1 0.01" material="grid"/>

    <!-- Glovebox main chamber (sealed box) -->
    <body name="glovebox_chamber" pos="0 0 0.3">
      <!-- Glovebox walls and interior -->
      <geom name="gb_floor" type="box" size="0.35 0.35 0.02" pos="0 0 -0.28" material="glovebox_material"/>
      <geom name="gb_back_wall" type="box" size="0.35 0.02 0.25" pos="0 0.35 -0.05" material="glovebox_material"/>
      <geom name="gb_front_wall" type="box" size="0.35 0.02 0.25" pos="0 -0.35 -0.05" material="glovebox_material"/>
      <geom name="gb_left_wall" type="box" size="0.02 0.35 0.25" pos="-0.35 0 -0.05" material="glovebox_material"/>
      <geom name="gb_right_wall" type="box" size="0.02 0.35 0.25" pos="0.35 0 -0.05" material="glovebox_material"/>

      <!-- Work surface (shelf inside glovebox) -->
      <body name="work_surface" pos="0 0.1 -0.15">
        <geom name="work_surface_geom" type="box" size="0.3 0.2 0.01" material="glovebox_material"/>
      </body>

      <!-- Payload area (container holder) -->
      <body name="payload_area" pos="0 -0.15 -0.15">
        <geom name="payload_geom" type="box" size="0.25 0.15 0.01" material="glovebox_material"/>
      </body>
    </body>

    <!-- Left Allegro Hand -->
    <body name="glovebox_left_hand" pos="-0.1 -0.3 0.5">
      <inertial pos="0 0 0" mass="1.0"/>
      <geom name="left_hand_base" type="box" size="0.05 0.04 0.03" material="hand_material"/>

      <!-- Include left hand kinematic structure -->
      <body name="left_hand_link_0" pos="0 0 0.05">
        <inertial pos="0 0 0" mass="0.1"/>
        <geom type="cylinder" size="0.01 0.03" material="hand_material"/>
        <joint name="left_hand_joint_0" type="hinge" axis="1 0 0" range="-1.57 1.57" damping="0.05"/>

        <body name="left_hand_link_1" pos="0 0 0.04">
          <inertial pos="0 0 0" mass="0.08"/>
          <geom type="cylinder" size="0.009 0.03" material="hand_material"/>
          <joint name="left_hand_joint_1" type="hinge" axis="1 0 0" range="-1.57 1.57" damping="0.05"/>

          <body name="left_hand_link_2" pos="0 0 0.035">
            <inertial pos="0 0 0" mass="0.06"/>
            <geom type="cylinder" size="0.008 0.025" material="hand_material"/>
            <joint name="left_hand_joint_2" type="hinge" axis="1 0 0" range="-1.57 1.57" damping="0.05"/>

            <body name="left_hand_link_3" pos="0 0 0.03">
              <inertial pos="0 0 0" mass="0.05"/>
              <geom type="cylinder" size="0.007 0.02" material="hand_material"/>
              <joint name="left_hand_joint_3" type="hinge" axis="1 0 0" range="-1.57 1.57" damping="0.05"/>

              <site name="left_thumb_touch" type="sphere" size="0.005" pos="0 0 0.02" material="red"/>
              <site name="left_thumb_touch_1" type="sphere" size="0.005" pos="0 0.01 0.02" material="red"/>
            </body>
          </body>
        </body>
      </body>

      <!-- Index finger chain -->
      <body name="left_hand_link_4" pos="0.02 0 0.05">
        <inertial pos="0 0 0" mass="0.1"/>
        <geom type="cylinder" size="0.01 0.03" material="hand_material"/>
        <joint name="left_hand_joint_4" type="hinge" axis="1 0 0" range="-1.57 1.57" damping="0.05"/>

        <body name="left_hand_link_5" pos="0 0 0.04">
          <inertial pos="0 0 0" mass="0.08"/>
          <geom type="cylinder" size="0.009 0.03" material="hand_material"/>
          <joint name="left_hand_joint_5" type="hinge" axis="1 0 0" range="-1.57 1.57" damping="0.05"/>

          <body name="left_hand_link_6" pos="0 0 0.035">
            <inertial pos="0 0 0" mass="0.06"/>
            <geom type="cylinder" size="0.008 0.025" material="hand_material"/>
            <joint name="left_hand_joint_6" type="hinge" axis="1 0 0" range="-1.57 1.57" damping="0.05"/>

            <body name="left_hand_link_7" pos="0 0 0.03">
              <inertial pos="0 0 0" mass="0.05"/>
              <geom type="cylinder" size="0.007 0.02" material="hand_material"/>
              <joint name="left_hand_joint_7" type="hinge" axis="1 0 0" range="-1.57 1.57" damping="0.05"/>

              <site name="left_index_touch" type="sphere" size="0.005" pos="0 0 0.02" material="red"/>
              <site name="left_index_touch_1" type="sphere" size="0.005" pos="0 0.01 0.02" material="red"/>
            </body>
          </body>
        </body>
      </body>

      <!-- Middle finger chain -->
      <body name="left_hand_link_8" pos="0.04 0 0.05">
        <inertial pos="0 0 0" mass="0.1"/>
        <geom type="cylinder" size="0.01 0.03" material="hand_material"/>
        <joint name="left_hand_joint_8" type="hinge" axis="1 0 0" range="-1.57 1.57" damping="0.05"/>

        <body name="left_hand_link_9" pos="0 0 0.04">
          <inertial pos="0 0 0" mass="0.08"/>
          <geom type="cylinder" size="0.009 0.03" material="hand_material"/>
          <joint name="left_hand_joint_9" type="hinge" axis="1 0 0" range="-1.57 1.57" damping="0.05"/>

          <body name="left_hand_link_10" pos="0 0 0.035">
            <inertial pos="0 0 0" mass="0.06"/>
            <geom type="cylinder" size="0.008 0.025" material="hand_material"/>
            <joint name="left_hand_joint_10" type="hinge" axis="1 0 0" range="-1.57 1.57" damping="0.05"/>

            <body name="left_hand_link_11" pos="0 0 0.03">
              <inertial pos="0 0 0" mass="0.05"/>
              <geom type="cylinder" size="0.007 0.02" material="hand_material"/>
              <joint name="left_hand_joint_11" type="hinge" axis="1 0 0" range="-1.57 1.57" damping="0.05"/>

              <site name="left_middle_touch" type="sphere" size="0.005" pos="0 0 0.02" material="red"/>
              <site name="left_middle_touch_1" type="sphere" size="0.005" pos="0 0.01 0.02" material="red"/>
            </body>
          </body>
        </body>
      </body>

      <!-- Ring finger chain -->
      <body name="left_hand_link_12" pos="0.06 0 0.05">
        <inertial pos="0 0 0" mass="0.1"/>
        <geom type="cylinder" size="0.01 0.03" material="hand_material"/>
        <joint name="left_hand_joint_12" type="hinge" axis="1 0 0" range="-1.57 1.57" damping="0.05"/>

        <body name="left_hand_link_13" pos="0 0 0.04">
          <inertial pos="0 0 0" mass="0.08"/>
          <geom type="cylinder" size="0.009 0.03" material="hand_material"/>
          <joint name="left_hand_joint_13" type="hinge" axis="1 0 0" range="-1.57 1.57" damping="0.05"/>

          <body name="left_hand_link_14" pos="0 0 0.035">
            <inertial pos="0 0 0" mass="0.06"/>
            <geom type="cylinder" size="0.008 0.025" material="hand_material"/>
            <joint name="left_hand_joint_14" type="hinge" axis="1 0 0" range="-1.57 1.57" damping="0.05"/>

            <body name="left_hand_link_15" pos="0 0 0.03">
              <inertial pos="0 0 0" mass="0.05"/>
              <geom type="cylinder" size="0.007 0.02" material="hand_material"/>
              <joint name="left_hand_joint_15" type="hinge" axis="1 0 0" range="-1.57 1.57" damping="0.05"/>

              <site name="left_ring_touch" type="sphere" size="0.005" pos="0 0 0.02" material="red"/>
              <site name="left_ring_touch_1" type="sphere" size="0.005" pos="0 0.01 0.02" material="red"/>
            </body>
          </body>
        </body>
      </body>
    </body>

    <!-- Right Allegro Hand (mirror of left) -->
    <body name="glovebox_right_hand" pos="0.1 -0.3 0.5">
      <inertial pos="0 0 0" mass="1.0"/>
      <geom name="right_hand_base" type="box" size="0.05 0.04 0.03" material="hand_material"/>

      <!-- Thumb chain -->
      <body name="right_hand_link_0" pos="0 0 0.05">
        <inertial pos="0 0 0" mass="0.1"/>
        <geom type="cylinder" size="0.01 0.03" material="hand_material"/>
        <joint name="right_hand_joint_0" type="hinge" axis="1 0 0" range="-1.57 1.57" damping="0.05"/>

        <body name="right_hand_link_1" pos="0 0 0.04">
          <inertial pos="0 0 0" mass="0.08"/>
          <geom type="cylinder" size="0.009 0.03" material="hand_material"/>
          <joint name="right_hand_joint_1" type="hinge" axis="1 0 0" range="-1.57 1.57" damping="0.05"/>

          <body name="right_hand_link_2" pos="0 0 0.035">
            <inertial pos="0 0 0" mass="0.06"/>
            <geom type="cylinder" size="0.008 0.025" material="hand_material"/>
            <joint name="right_hand_joint_2" type="hinge" axis="1 0 0" range="-1.57 1.57" damping="0.05"/>

            <body name="right_hand_link_3" pos="0 0 0.03">
              <inertial pos="0 0 0" mass="0.05"/>
              <geom type="cylinder" size="0.007 0.02" material="hand_material"/>
              <joint name="right_hand_joint_3" type="hinge" axis="1 0 0" range="-1.57 1.57" damping="0.05"/>

              <site name="right_thumb_touch" type="sphere" size="0.005" pos="0 0 0.02" material="blue"/>
              <site name="right_thumb_touch_1" type="sphere" size="0.005" pos="0 0.01 0.02" material="blue"/>
            </body>
          </body>
        </body>
      </body>

      <!-- Index finger chain -->
      <body name="right_hand_link_4" pos="-0.02 0 0.05">
        <inertial pos="0 0 0" mass="0.1"/>
        <geom type="cylinder" size="0.01 0.03" material="hand_material"/>
        <joint name="right_hand_joint_4" type="hinge" axis="1 0 0" range="-1.57 1.57" damping="0.05"/>

        <body name="right_hand_link_5" pos="0 0 0.04">
          <inertial pos="0 0 0" mass="0.08"/>
          <geom type="cylinder" size="0.009 0.03" material="hand_material"/>
          <joint name="right_hand_joint_5" type="hinge" axis="1 0 0" range="-1.57 1.57" damping="0.05"/>

          <body name="right_hand_link_6" pos="0 0 0.035">
            <inertial pos="0 0 0" mass="0.06"/>
            <geom type="cylinder" size="0.008 0.025" material="hand_material"/>
            <joint name="right_hand_joint_6" type="hinge" axis="1 0 0" range="-1.57 1.57" damping="0.05"/>

            <body name="right_hand_link_7" pos="0 0 0.03">
              <inertial pos="0 0 0" mass="0.05"/>
              <geom type="cylinder" size="0.007 0.02" material="hand_material"/>
              <joint name="right_hand_joint_7" type="hinge" axis="1 0 0" range="-1.57 1.57" damping="0.05"/>

              <site name="right_index_touch" type="sphere" size="0.005" pos="0 0 0.02" material="blue"/>
              <site name="right_index_touch_1" type="sphere" size="0.005" pos="0 0.01 0.02" material="blue"/>
            </body>
          </body>
        </body>
      </body>

      <!-- Middle finger chain -->
      <body name="right_hand_link_8" pos="-0.04 0 0.05">
        <inertial pos="0 0 0" mass="0.1"/>
        <geom type="cylinder" size="0.01 0.03" material="hand_material"/>
        <joint name="right_hand_joint_8" type="hinge" axis="1 0 0" range="-1.57 1.57" damping="0.05"/>

        <body name="right_hand_link_9" pos="0 0 0.04">
          <inertial pos="0 0 0" mass="0.08"/>
          <geom type="cylinder" size="0.009 0.03" material="hand_material"/>
          <joint name="right_hand_joint_9" type="hinge" axis="1 0 0" range="-1.57 1.57" damping="0.05"/>

          <body name="right_hand_link_10" pos="0 0 0.035">
            <inertial pos="0 0 0" mass="0.06"/>
            <geom type="cylinder" size="0.008 0.025" material="hand_material"/>
            <joint name="right_hand_joint_10" type="hinge" axis="1 0 0" range="-1.57 1.57" damping="0.05"/>

            <body name="right_hand_link_11" pos="0 0 0.03">
              <inertial pos="0 0 0" mass="0.05"/>
              <geom type="cylinder" size="0.007 0.02" material="hand_material"/>
              <joint name="right_hand_joint_11" type="hinge" axis="1 0 0" range="-1.57 1.57" damping="0.05"/>

              <site name="right_middle_touch" type="sphere" size="0.005" pos="0 0 0.02" material="blue"/>
              <site name="right_middle_touch_1" type="sphere" size="0.005" pos="0 0.01 0.02" material="blue"/>
            </body>
          </body>
        </body>
      </body>

      <!-- Ring finger chain -->
      <body name="right_hand_link_12" pos="-0.06 0 0.05">
        <inertial pos="0 0 0" mass="0.1"/>
        <geom type="cylinder" size="0.01 0.03" material="hand_material"/>
        <joint name="right_hand_joint_12" type="hinge" axis="1 0 0" range="-1.57 1.57" damping="0.05"/>

        <body name="right_hand_link_13" pos="0 0 0.04">
          <inertial pos="0 0 0" mass="0.08"/>
          <geom type="cylinder" size="0.009 0.03" material="hand_material"/>
          <joint name="right_hand_joint_13" type="hinge" axis="1 0 0" range="-1.57 1.57" damping="0.05"/>

          <body name="right_hand_link_14" pos="0 0 0.035">
            <inertial pos="0 0 0" mass="0.06"/>
            <geom type="cylinder" size="0.008 0.025" material="hand_material"/>
            <joint name="right_hand_joint_14" type="hinge" axis="1 0 0" range="-1.57 1.57" damping="0.05"/>

            <body name="right_hand_link_15" pos="0 0 0.03">
              <inertial pos="0 0 0" mass="0.05"/>
              <geom type="cylinder" size="0.007 0.02" material="hand_material"/>
              <joint name="right_hand_joint_15" type="hinge" axis="1 0 0" range="-1.57 1.57" damping="0.05"/>

              <site name="right_ring_touch" type="sphere" size="0.005" pos="0 0 0.02" material="blue"/>
              <site name="right_ring_touch_1" type="sphere" size="0.005" pos="0 0.01 0.02" material="blue"/>
            </body>
          </body>
        </body>
      </body>
    </body>

    <!-- Sample vial (object to manipulate) -->
    <body name="sample_vial" pos="-0.15 0.3 0.1">
      <inertial pos="0 0 0" mass="0.05"/>
      <!-- Cylinder body -->
      <geom type="cylinder" size="0.01 0.03" material="red"/>
      <!-- Box cap -->
      <geom type="box" size="0.008 0.008 0.005" pos="0 0 0.035" material="red"/>
    </body>

    <!-- Shielded container (payload) -->
    <body name="shielded_container" pos="0.15 0.3 0.05">
      <inertial pos="0 0 0" mass="0.2"/>
      <geom type="box" size="0.06 0.08 0.04" material="blue"/>
    </body>
  </worldbody>

  <actuator>
    <!-- Left hand motors -->
    <motor name="left_hand_motor_0" joint="left_hand_joint_0" gear="1" ctrlrange="-1.0 1.0"/>
    <motor name="left_hand_motor_1" joint="left_hand_joint_1" gear="1" ctrlrange="-1.0 1.0"/>
    <motor name="left_hand_motor_2" joint="left_hand_joint_2" gear="1" ctrlrange="-1.0 1.0"/>
    <motor name="left_hand_motor_3" joint="left_hand_joint_3" gear="1" ctrlrange="-1.0 1.0"/>
    <motor name="left_hand_motor_4" joint="left_hand_joint_4" gear="1" ctrlrange="-1.0 1.0"/>
    <motor name="left_hand_motor_5" joint="left_hand_joint_5" gear="1" ctrlrange="-1.0 1.0"/>
    <motor name="left_hand_motor_6" joint="left_hand_joint_6" gear="1" ctrlrange="-1.0 1.0"/>
    <motor name="left_hand_motor_7" joint="left_hand_joint_7" gear="1" ctrlrange="-1.0 1.0"/>
    <motor name="left_hand_motor_8" joint="left_hand_joint_8" gear="1" ctrlrange="-1.0 1.0"/>
    <motor name="left_hand_motor_9" joint="left_hand_joint_9" gear="1" ctrlrange="-1.0 1.0"/>
    <motor name="left_hand_motor_10" joint="left_hand_joint_10" gear="1" ctrlrange="-1.0 1.0"/>
    <motor name="left_hand_motor_11" joint="left_hand_joint_11" gear="1" ctrlrange="-1.0 1.0"/>
    <motor name="left_hand_motor_12" joint="left_hand_joint_12" gear="1" ctrlrange="-1.0 1.0"/>
    <motor name="left_hand_motor_13" joint="left_hand_joint_13" gear="1" ctrlrange="-1.0 1.0"/>
    <motor name="left_hand_motor_14" joint="left_hand_joint_14" gear="1" ctrlrange="-1.0 1.0"/>
    <motor name="left_hand_motor_15" joint="left_hand_joint_15" gear="1" ctrlrange="-1.0 1.0"/>

    <!-- Right hand motors -->
    <motor name="right_hand_motor_0" joint="right_hand_joint_0" gear="1" ctrlrange="-1.0 1.0"/>
    <motor name="right_hand_motor_1" joint="right_hand_joint_1" gear="1" ctrlrange="-1.0 1.0"/>
    <motor name="right_hand_motor_2" joint="right_hand_joint_2" gear="1" ctrlrange="-1.0 1.0"/>
    <motor name="right_hand_motor_3" joint="right_hand_joint_3" gear="1" ctrlrange="-1.0 1.0"/>
    <motor name="right_hand_motor_4" joint="right_hand_joint_4" gear="1" ctrlrange="-1.0 1.0"/>
    <motor name="right_hand_motor_5" joint="right_hand_joint_5" gear="1" ctrlrange="-1.0 1.0"/>
    <motor name="right_hand_motor_6" joint="right_hand_joint_6" gear="1" ctrlrange="-1.0 1.0"/>
    <motor name="right_hand_motor_7" joint="right_hand_joint_7" gear="1" ctrlrange="-1.0 1.0"/>
    <motor name="right_hand_motor_8" joint="right_hand_joint_8" gear="1" ctrlrange="-1.0 1.0"/>
    <motor name="right_hand_motor_9" joint="right_hand_joint_9" gear="1" ctrlrange="-1.0 1.0"/>
    <motor name="right_hand_motor_10" joint="right_hand_joint_10" gear="1" ctrlrange="-1.0 1.0"/>
    <motor name="right_hand_motor_11" joint="right_hand_joint_11" gear="1" ctrlrange="-1.0 1.0"/>
    <motor name="right_hand_motor_12" joint="right_hand_joint_12" gear="1" ctrlrange="-1.0 1.0"/>
    <motor name="right_hand_motor_13" joint="right_hand_joint_13" gear="1" ctrlrange="-1.0 1.0"/>
    <motor name="right_hand_motor_14" joint="right_hand_joint_14" gear="1" ctrlrange="-1.0 1.0"/>
    <motor name="right_hand_motor_15" joint="right_hand_joint_15" gear="1" ctrlrange="-1.0 1.0"/>
  </actuator>
</mujoco>
